Workbook

Sheet 공종별집계
A1: 공종별집계 - 바닥 마감 (목공사및수장공사 중)
A2: 수량 = 산출근거서 합계(SUMIFS). 도면 기준 = PDF 벡터 측정, 내역서 = 발주처 공개 공내역서(2022). 수량은 정미량(할증은 일위대가에서 처리).
A4: 품명 | B4: 규격 | C4: 단위 | D4: AI 산출 수량 | E4: 도면 기준(벡터) | F4: 내역서 수량 | G4: AI-도면 오차 | H4: AI-내역 차이 | I4: 비고
A5: 비닐타일 깔기 [DE-01] | B5: 디럭스타일 THK3 (도면 범례 450x450) | C5: M2 | D5: =SUMIFS(산출근거서!$G$5:$G$40,산출근거서!$D$5:$D$40,"DE-01") | E5: 66.08 | F5: 59 | G5: =(D5-E5)/E5 | H5: =D5-F5 | I5: 내역서 규격 300x300 ↔ 도면 450x450 (규격 불일치 확인 필요)
A6: 비닐타일 깔기 [DT-01] | B6: 데코타일 (MATERIAL LIST 600x600 T5) | C6: M2 | D6: =SUMIFS(산출근거서!$G$5:$G$40,산출근거서!$D$5:$D$40,"DT-01") | E6: 43.11 | F6: 88 | G6: =(D6-E6)/E6 | H6: =D6-F6 | I6: 내역서 규격 450x450 ↔ MATERIAL LIST 600x600 (규격 불일치 확인 필요)
A7: 비닐타일 깔기 [DT-02] | B7: 데코타일 457x914 | C7: M2 | D7: =SUMIFS(산출근거서!$G$5:$G$40,산출근거서!$D$5:$D$40,"DT-02") | E7: 246.72 | F7: 283 | G7: =(D7-E7)/E7 | H7: =D7-F7
A8: 비닐타일 깔기 [DT-03] | B8: 데코타일 457x914 | C8: M2 | D8: =SUMIFS(산출근거서!$G$5:$G$40,산출근거서!$D$5:$D$40,"DT-03") | E8: 469.75 | F8: 492 | G8: =(D8-E8)/E8 | H8: =D8-F8
A9: 타일카펫 깔기 [CT-01] | B9: 타일카펫 610x610 | C9: M2 | D9: =SUMIFS(산출근거서!$G$5:$G$40,산출근거서!$D$5:$D$40,"CT-01") | E9: 199.91 | F9: 101 | G9: =(D9-E9)/E9 | H9: =D9-F9 | I9: B1 다목적 대회의실 단상(우드플로링) AI가 약 9.4㎡ 공제 (내역 단상 6000x1200=7.2㎡)
A10: 타일카펫 깔기 [CT-02] | B10: 타일카펫 610x610 | C10: M2 | D10: =SUMIFS(산출근거서!$G$5:$G$40,산출근거서!$D$5:$D$40,"CT-02") | E10: 97.28 | F10: 79 | G10: =(D10-E10)/E10 | H10: =D10-F10
A11: 타일카펫 깔기 [CT-03] | B11: 타일카펫 610x610 | C11: M2 | D11: =SUMIFS(산출근거서!$G$5:$G$40,산출근거서!$D$5:$D$40,"CT-03") | E11: 74.73 | F11: 111 | G11: =(D11-E11)/E11 | H11: =D11-F11
A12: 타일카펫 깔기 [CT-04] | B12: 타일카펫 | C12: M2 | D12: 0 | E12: 0 | F12: 88 | H12: =D12-F12 | I12: 도면 범례·MATERIAL LIST에 없는 코드. 내역 CT 번호 체계가 도면과 달라(내역 CT-01 101㎡ < 도면 CT-01인 B1 대회의실 135㎡) 코드별 대조 불가 → 아래 종류별 대조 참고
A13: 타일카펫 깔기 [CT-05] | B13: 타일카펫 | C13: M2 | D13: 0 | E13: 0 | F13: 22 | H13: =D13-F13 | I13: 도면 범례·MATERIAL LIST에 없는 코드. 내역 CT 번호 체계가 도면과 달라(내역 CT-01 101㎡ < 도면 CT-01인 B1 대회의실 135㎡) 코드별 대조 불가 → 아래 종류별 대조 참고
A14: 바닥 마감 소계 | D14: =SUM(D5:D13) | E14: =SUM(E5:E13) | F14: =SUM(F5:F13) | G14: =(D14-E14)/E14 | H14: =D14-F14 | I14: 참고: 내역서 '기존면바탕정리(바닥)' 1,324㎡ ≈ 바닥재 합 1,323㎡ → 내역 수량은 정미량
A15: 걸레받이 설치 - MDF+인테리어필름 | B15: T=9, H=30 (내역서 규격) | C15: M | D15: =SUM(산출근거서!$H$5:$H$40) | F15: 765 | H15: =D15-F15 | I15: 미해결: AI 산출이 내역 대비 약 -40%. 열린 사무실·복도 둘레, 가구 뒤, 기둥 둘레 처리 기준 확인 필요
A17: 자재 종류별 대조 (코드 번호 체계 차이를 피해서 비교)
A18: 종류 | C18: 단위 | D18: AI 산출 | E18: 도면 기준(벡터) | F18: 내역서 | G18: AI-도면 오차 | H18: 도면-내역 차이 | I18: 해석
A19: DE 디럭스타일 | C19: M2 | D19: =D5 | E19: =E5 | F19: =F5 | G19: =(D19-E19)/E19 | H19: =F19-E19 | I19: 도면이 7㎡ 많음 - 태그 해석 차이(2F 금고 P-TILE 문구 등)
A20: DT 데코타일 | C20: M2 | D20: =D6+D7+D8 | E20: =E6+E7+E8 | F20: =F6+F7+F8 | G20: =(D20-E20)/E20 | H20: =F20-E20 | I20: 내역이 103㎡ 많음 - 무코드 실·미표기 구역 포함 추정
A21: CT 타일카펫 | C21: M2 | D21: =D9+D10+D11+D12+D13 | E21: =E9+E10+E11+E12+E13 | F21: =F9+F10+F11+F12+F13 | G21: =(D21-E21)/E21 | H21: =F21-E21 | I21: 내역이 29㎡ 많음 - 창측 띠/단상 처리 차이 추정

Sheet 실별 산출서
A1: 실별 산출서 - 실마다 면적 A·둘레 L·걸레받이 B를 먼저 정하고, 마감 품목은 그 변수로 계산
A2: 파란 글씨 = AI가 도면에서 읽은 값. 물량 칸은 수식(변수 셀 참조). 형상 그림은 AI가 읽은 가로×세로로 그린 단순화 도형. 비정형 실은 가산·공제를 산식에 따로 표시.
A4: 도형 | B4: 부위 | C4: 품명 | D4: 규격 | E4: 단위 | F4: 산식 | G4: 물량
A5: 실명 : B1 다목적 대회의실 | C5: 개소 : 1 | F5: 신뢰도 mid
A6: A | B6: (면 적) | F6: 11.160 × 12.000 = 133.920 -9.870<공제 - 산출근거서 No.1> | G6: 124.05
A7: L | B7: (둘 레) | F7: 비정형 - 사각형 근사 생략
A8: B | B8: (걸레받이) | F8: 둘레 − 개구부(문·폴딩도어) - 산출근거서 No.1 | G8: 38.14
A9: H | B9: (마감높이) | F9: 바닥 마감 범위 외
B10: [산 출 범 위]
B11: 바닥 | C11: 타일카펫 깔기 [CT-01] | D11: 타일카펫 610x610 | E11: M2 | F11: A<면적> − 0<기둥 공제> | G11: =G6-0
B12: 걸레받이 | C12: 걸레받이 설치 | D12: MDF+인테리어필름 T=9, H=30 | E12: M | F12: B<걸레받이> | G12: =G8
B13: [ 끝 ]
A15: 도형 | B15: 부위 | C15: 품명 | D15: 규격 | E15: 단위 | F15: 산식 | G15: 물량
A16: 실명 : B1 서고 | C16: 개소 : 1 | F16: 신뢰도 low
A17: A | B17: (면 적) | F17: 6.930 × 4.560 = 31.601 +3.829<가산 - 산출근거서 No.2> | G17: 35.43
A18: L | B18: (둘 레) | F18: 비정형 - 사각형 근사 생략
A19: B | B19: (걸레받이) | F19: 둘레 − 개구부(문·폴딩도어) - 산출근거서 No.2 | G19: 25.5
A20: H | B20: (마감높이) | F20: 바닥 마감 범위 외
B21: [산 출 범 위]
B22: 바닥 | C22: 비닐타일 깔기 [DE-01] | D22: 디럭스타일 THK3 (도면 범례 450x450) | E22: M2 | F22: A<면적> − 0<기둥 공제> | G22: =G17-0
B23: 걸레받이 | C23: 걸레받이 설치 | D23: MDF+인테리어필름 T=9, H=30 | E23: M | F23: B<걸레받이> | G23: =G19
B24: [ 끝 ]
A26: 도형 | B26: 부위 | C26: 품명 | D26: 규격 | E26: 단위 | F26: 산식 | G26: 물량
A27: 실명 : B1 기자실 | C27: 개소 : 1 | F27: 신뢰도 high
A28: A | B28: (면 적) | F28: 4.100 × 2.950 = 12.095 | G28: 12.09
A29: L | B29: (둘 레) | F29: 2 × (4.100 + 2.950) | G29: =ROUND(2*(4.1+2.95),3)
A30: B | B30: (걸레받이) | F30: 둘레 − 개구부(문·폴딩도어) - 산출근거서 No.3 | G30: 13.1
A31: H | B31: (마감높이) | F31: 바닥 마감 범위 외
B32: [산 출 범 위]
B33: 바닥 | C33: 비닐타일 깔기 [DE-01] | D33: 디럭스타일 THK3 (도면 범례 450x450) | E33: M2 | F33: A<면적> − 0<기둥 공제> | G33: =G28-0
B34: 걸레받이 | C34: 걸레받이 설치 | D34: MDF+인테리어필름 T=9, H=30 | E34: M | F34: B<걸레받이> | G34: =G30
B35: [ 끝 ]
A37: 도형 | B37: 부위 | C37: 품명 | D37: 규격 | E37: 단위 | F37: 산식 | G37: 물량
A38: 실명 : B1 기사대기실 | C38: 개소 : 1 | F38: 신뢰도 mid
A39: A | B39: (면 적) | F39: 2.000 × 2.050 = 4.100 | G39: 4.1
A40: L | B40: (둘 레) | F40: 2 × (2.000 + 2.050) | G40: =ROUND(2*(2.0+2.05),3)
A41: B | B41: (걸레받이) | F41: 둘레 − 개구부(문·폴딩도어) - 산출근거서 No.4 | G41: 7.16
A42: H | B42: (마감높이) | F42: 바닥 마감 범위 외
B43: [산 출 범 위]
B44: 바닥 | C44: 비닐타일 깔기 [DE-01] | D44: 디럭스타일 THK3 (도면 범례 450x450) | E44: M2 | F44: A<면적> − 0<기둥 공제> | G44: =G39-0
...

Sheet 산출근거서
A1: 산출근거서 - 대한변호사협회 신회관 인테리어 공사 / 바닥 마감 (AI 산출 v6)
A2: 파란 글씨 = AI가 도면에서 읽은 값(입력값). 오차 열은 수식. 도면 기준 = PDF 벡터 정밀 측정(벽으로 닫힌 실만).
A4: No | B4: 층 | C4: 실명 | D4: 마감코드 | E4: 가로(mm) | F4: 세로(mm) | G4: 면적(㎡) | H4: 걸레받이(m) | I4: 산출 근거 (도면·치수) | J4: 신뢰도 | K4: 검토 기록 | L4: 도면 기준(㎡) | M4: 오차(%)
A5: 1 | B5: B1 | C5: 다목적 대회의실 | D5: CT-01 | E5: 11160 | F5: 12000 | G5: 124.05 | H5: 38.14 | I5: B1_dimension_SE: 11450(안목 직전 성벽~동측벽) 에서 신설 차음벽(점선) 위치 offset 약290 공제 => w=11160; B1_material_NE: 세로 '12000' 숫자 사용 d=12000. 11.16x12.0=133.92. R2: 독립기둥 약0.77x0.58=0.45 공제. 단상(APP' WOOD FLOORING, 카펫 아님) 약6.24x1.51=9.4(도면 비례 추정) 공제. 걸레받이=둘레46.32-남측 쌍여닫이 1940(B1_dimension_SE '1940')-서측문 0.9-0.98-단상 정면 6.24=36.26 || [v5 수정] 걸레받이=둘레 2*(11.16+12.0)=46.32 - 남측 쌍여닫이 1.94 - 단상 정면 6.24 = 38.14. 서측 차음벽 문 공제 삭제. 안목: 11450(코어벽~D.A벽)에서 차음벽 점선 offset 약240~290 공제(R1)는 v4 유지. | J5: mid | K5: 걸레받이 수정 36.26->38.14, 면적 124.11->124.05. v4가 서측 문 0.9+0.98을 공제했으나 그 문들은 B1_material_NE 의 법률구조재단/ELE'V HALL 쪽 문이고 대회의실 서측 차음벽(점선)에는 문이 없음. 대회의실 출입문은 남측 쌍여닫이 1940 하나. 면적은 11.16x12.0-기둥0.45-단상 6.24x1.51(9.42)=124.05로 재계산. | v6: B1은 창·커튼월 접면 없음(동측 D.A는 벽 바깥 선큰, 11450 치수가 벽 안쪽까지) -> 띠 없음, v5 유지 | L5: 135.11 | M5: =IFERROR((G5-L5)/L5,"")
A6: 2 | B6: B1 | C6: 서고 | D6: DE-01 | E6: 6930 | F6: 4560 | G6: 35.43 | H6: 25.5 | I6: B1_dimension_NW: 서고 실치수 숫자 없음 -> grid 7800(1열~2열 사이) 사용. R1: 좌측 외벽+마감 약460, 우측 CAR LIFT벽 약410 공제 => w=7800-460-410=6930. 깊이: 상부 그리드(0)~방송실 칸막이 중심(약5020, 7300 그리드 비례) - 상부벽 400 - 칸막이 반두께100 = 4560. 방송실(무코드, 제외) 동쪽 L형 연장부(문 있는 통로) 1.7x2.25 가산 = 31.61+3.83=35.44. 6.93x4.56. 칸막이 위치는 도면 비례 추정이라 정확도 낮음. 걸레받이=외곽 약28.0-문(방송실 문1.0+하부 출입문1.2)=25.5 | J6: low | K6: ok (도면 재확인: 6930x4560 + 방송실 동측 통로 L부 유지. 칸막이 위치는 도면 비례라 low 유지) | v6: B1은 창·커튼월 접면 없음(동측 D.A는 벽 바깥 선큰, 11450 치수가 벽 안쪽까지) -> 띠 없음, v5 유지 | L6: 34.79 | M6: =IFERROR((G6-L6)/L6,"")
A7: 3 | B7: B1 | C7: 기자실 | D7: DE-01 | E7: 4100 | F7: 2950 | G7: 12.09 | H7: 13.1 | I7: B1_dimension_SE: 가로 500+1000+2600=4100, 세로 2950 숫자. 4.1x2.95. 걸레받이=2*(4.1+2.95)-문1000=13.1 | J7: high | K7: ok | v6: B1은 창·커튼월 접면 없음(동측 D.A는 벽 바깥 선큰, 11450 치수가 벽 안쪽까지) -> 띠 없음, v5 유지 | L7: 11.74 | M7: =IFERROR((G7-L7)/L7,"")
A8: 4 | B8: B1 | C8: 기사대기실 | D8: DE-01 | E8: 2000 | F8: 2050 | G8: 4.1 | H8: 7.16 | I8: B1_dimension_SE: 가로 1060+940=2000 (좌측 300 벽 제외), 세로 2050 숫자. 걸레받이=둘레8.1-문940=7.16. 재질도면에 DELUXE TILE FIN. 문구(코드 태그는 창고 옆 01 DE와 공유 표기) | J8: mid | K8: ok | v6: B1은 창·커튼월 접면 없음(동측 D.A는 벽 바깥 선큰, 11450 치수가 벽 안쪽까지) -> 띠 없음, v5 유지
A9: 5 | B9: B1 | C9: 창고 | D9: DE-01 | E9: 1700 | F9: 2850 | G9: 4.84 | H9: 8.1 | I9: B1_dimension_SE: 세로 1000+1850=2850 숫자, 가로는 숫자 없어 벽 중심~외벽 안쪽 도면비례 약1700(추정). 둘레9.1-문1.0=8.1 | J9: low | K9: ok | v6: B1은 창·커튼월 접면 없음(동측 D.A는 벽 바깥 선큰, 11450 치수가 벽 안쪽까지) -> 띠 없음, v5 유지 | L9: 5.17 | M9: =IFERROR((G9-L9)/L9,"")
A10: 6 | B10: B1 | C10: 이사장실 | D10: DT-01 | E10: 2849 | F10: 2495 | G10: 7.11 | H10: 8.19 | I10: B1_dimension_NE/NW: 가로 2849 x 세로 2495 (실 안쪽 치수 숫자). 재질도면 remark(DT-01: 법률구조재단, 이사장실)에 이사장실 포함. 걸레받이=2*(2.849+2.495)=10.69 - 동측 유리칸막이(문 포함) 2.495 = 8.19 | J10: mid | K10: ok | v6: B1은 창·커튼월 접면 없음(동측 D.A는 벽 바깥 선큰, 11450 치수가 벽 안쪽까지) -> 띠 없음, v5 유지
A11: 7 | B11: B1 | C11: 법률구조재단 | D11: DT-01 | E11: 7845 | F11: 5450 | G11: 31.57 | H11: 22.22 | I11: B1_dimension_NE: 7845(전체 가로) x (2495+105+2850=5450) = 42.76 에서 이사장실 2849x2495 공제, 준비실(무코드, 105+1690+105=1900 x 1883+105=1988) 공제, 이사장실 하부 벽 105x2849 공제 = 31.57. 걸레받이=코너 노치 제외 둘레 26.59 - 서측문0.9 - 동측문0.98(B1_dimension_NE '980') - 이사장실 유리칸막이 2.495 = 22.22 | J11: mid | K11: ok | v6: B1은 창·커튼월 접면 없음(동측 D.A는 벽 바깥 선큰, 11450 치수가 벽 안쪽까지) -> 띠 없음, v5 유지 | L11: 32.9 | M11: =IFERROR((G11-L11)/L11,"")
A12: 8 | B12: 2F | C12: 여직원휴게실(수유실) | D12: CT-02 | E12: 2196 | F12: 4045 | G12: 8.55 | H12: 11.5 | I12: 2F_dimension_NE: 가로 1116+1080=2196, 세로 4045 숫자; 좌측 1116폭 구간은 295 만큼 짧음(2F_dimension_NE '295') => 1.116x3.75+1.08x4.045=4.19+4.37. 걸레받이=둘레12.48-문 980=11.5 | J12: mid | K12: ok | v6: 외벽(창) 접면 없음/무수치 북벽 -> 띠 변경 없음 | L12: 8.23 | M12: =IFERROR((G12-L12)/L12,"")
A13: 9 | B13: 2F | C13: 소회의실-1 | D13: CT-02 | E13: 3205 | F13: 3900 | G13: 12.29 | H13: 5.13 | I13: 2F_dimension_SW: 가로 3205, 세로 3345(2F_dimension_SE '3345', SW '3390'은 중심선 기준이라 3345 채택). 걸레받이=서벽3.345+동측 폴딩도어 칸막이3.345 (전면 유리·남측 창 제외; 폴딩 칸막이를 양쪽 실에 반영한 가정) || [v5 수정] 걸레받이=서측 고정벽 3.345 + 남측 불투명 외벽 1.78 = 5.13 (동측 폴딩도어, 전면 유리 제외). || [v6 창측 띠] 2F_dimension_SW '3390'/SE '3345' 끝~창 '555' x 가로 3205 - 그리드2 기둥 약0.21. 계산: 남측 555x3.205=+1.78 + 기둥1 공제=-0.21 = +1.57. 걸레받이는 창 하부(FCU 박스)라 변경 없음. | J13: mid | K13: 창측 띠 +1.57㎡ (2F_dimension_SW '3390'/SE '3345' 끝~창 '555' x 가로 3205 - 그리드2 기둥 약0.21). 면적 10.72->12.29. 이전 review: 걸레받이 수정 6.69->5.13. 폴딩도어(ESC-04) 칸막이는 이동식이라 걸레받이 없음(R5 벽이 있는 구간만). 서측 고정벽 3.345만 인정. 반대로 남측 외벽 불투명 기둥/벽체 구간 약1.78m(2F_dimension_SW 하단 진한 벽체 x950~1080)가 누락되어 추가. | L13: 12.39 | M13: =IFERROR((G13-L13)/L13,"")
A14: 10 | B14: 2F | C14: 소회의실-2 | D14: CT-02 | E14: 3203 | F14: 3900 | G14: 12.49 | H14: 0 | I14: 2F_dimension_SW/SE: 가로 3203, 세로 3345. 걸레받이=양측 폴딩도어 칸막이 3.345x2 (가정) || [v5 수정] 양측 폴딩도어, 전면 유리, 남측 유리 => 걸레받이 0. || [v6 창측 띠] 2F_dimension_SW/SE '3345' 끝~창 '555' x 가로 3203 (기둥 없음). 계산: 남측 555x3.203=+1.78 = +1.78. 걸레받이는 창 하부(FCU 박스)라 변경 없음. | J14: mid | K14: 창측 띠 +1.78㎡ (2F_dimension_SW/SE '3345' 끝~창 '555' x 가로 3203 (기둥 없음)). 면적 10.71->12.49. 이전 review: 걸레받이 수정 6.69->0. 양측이 모두 폴딩도어 칸막이(이동식, 걸레받이 없음), 전면은 유리, 남측은 SE타일상 유리 커튼월. 벽 구간 없음. | L14: 13.15 | M14: =IFERROR((G14-L14)/L14,"")
A15: 11 | B15: 2F | C15: 소회의실-3 | D15: CT-02 | E15: 3203 | F15: 3900 | G15: 12.28 | H15: 3.35 | I15: 2F_dimension_SE: 가로 3203, 세로 3345. 걸레받이=서측 폴딩 3.345 + 동측 금고 벽 3.345 || [v5 수정] 걸레받이=동측 금고 고정벽 3.345 (서측 폴딩도어 제외). || [v6 창측 띠] 2F_dimension_SE '3345' 끝~창 '555' x 가로 3203 - 동측 기둥 약0.21. 계산: 남측 555x3.203=+1.78 + 기둥1 공제=-0.21 = +1.57. 걸레받이는 창 하부(FCU 박스)라 변경 없음. | J15: mid | K15: 창측 띠 +1.57㎡ (2F_dimension_SE '3345' 끝~창 '555' x 가로 3203 - 동측 기둥 약0.21). 면적 10.71->12.28. 이전 review: 걸레받이 수정 6.69->3.35. 서측은 폴딩도어(걸레받이 없음), 동측 금고 벽 3.345만 고정벽. | L15: 12.84 | M15: =IFERROR((G15-L15)/L15,"")
A16: 12 | B16: 2F | C16: 금고 | D16: DE-01 | E16: 1673 | F16: 3290 | G16: 5.5 | H16: 8.95 | I16: 2F_dimension_SE: 가로 1673, 세로 980+2310=3290 (205/105 벽 제외). 걸레받이=둘레9.93-문980=8.95 | J16: mid | K16: ok | v6: 외벽(창) 접면 없음/무수치 북벽 -> 띠 변경 없음 | L16: 4.87 | M16: =IFERROR((G16-L16)/L16,"")
A17: 13 | B17: 2F | C17: O.A RM (서측) | D17: DT-02 | E17: 1395 | F17: 4531 | G17: 6.32 | H17: 9.97 | I17: 2F_dimension_SW: 가로 190|1395|115 (안목 1395), 세로 4531 숫자. 재질도면 SW타일 태그 '02 DT'(overview는 03처럼 보이나 타일에서 02 확인). 걸레받이=둘레11.85-서측 개구 1880=9.97 | J17: high | K17: ok | v6: 외벽(창) 접면 없음/무수치 북벽 -> 띠 변경 없음
A18: 14 | B18: 2F | C18: CORRIDOR 서측 (INFO~O.A 옆) | D18: DT-02 | E18: 1600 | F18: 9753 | G18: 17.47 | H18: 14.75 | I18: 2F_dimension_NW: 1980(INFO 동측~화장실/코어벽) x 약4.93m(INFO 상단벽~O.A RM 상단) 9.76; 2F_dimension_SW: 1600(O.A RM 동벽~코어 서측, '1700|1600|400') x 4.82(O.A RM 구간~코어 하부) 7.71. 길이는 도면비례 추정. 걸레받이=화장실/코어벽3.4+INFO 상벽2.0+O.A동벽4.53+코어 서측5.4 약14.75 | J18: low | K18: ok | v6: 외벽(창) 접면 없음/무수치 북벽 -> 띠 변경 없음
A19: 15 | B19: 2F | C19: CORRIDOR 남측 | D19: DT-02 | E19: 12410 | F19: 2000 | G19: 24.82 | H19: 11.2 | I19: 2F_dimension_SW/SE: 세로 2000(코어 하부~소회의실 전면, SW '2000' 숫자) x 가로 F-2 전이선(SW x=893)~F-2 전이선(SE x=603) 중 O.A RM 동벽(x=820)부터 SE x=603까지 약13.43m(도면비례 추정). 걸레받이=코어 하부벽9.27+금고 전면1.9. 소회의실 전면 유리 제외 || [v5 수정] 복도 시작을 F-2 전이선(SW x=893)으로 변경: 길이 12.41m(13.7mm/px) x 2000 = 24.82. OFFICE 서측 보조구역과의 중복 1.0x2.0 제거(R4). 걸레받이 11.2 유지. | J19: low | K19: 이중계산 수정. 면적 26.86->24.82. v4가 복도 시작을 O.A RM 동벽(SW x=820)으로 잡았으나 OFFICE(DT-03) 보조구역(x 698~893, y 2000폭)이 F-2 전이선(SW x=893)까지 이미 들어가 있어 x 820~893 구간 약1.0m x 2.0m가 OFFICE와 겹쳤음. 복도는 F-2 전이선(SW x=893)부터 동측 F-2(SE x=603)까지 약12.41m로 정정. | v6: 외벽(창) 접면 없음/무수치 북벽 -> 띠 변경 없음
A20: 16 | B20: 2F | C20: CORRIDOR 동측 (코어~인권팀) | D20: DT-02 | E20: 1600 | F20: 7400 | G20: 11.84 | H20: 6.5 | I20: 2F_dimension_SE: 1600(코어 동측 덕트 끝~인권팀 서벽 숫자 '1600') x 길이 약7.63m(코어 상단~남측 복도, 도면비례). 걸레받이=코어 동측벽 6.5 (인권팀 서측은 유리 가정 0) || [v5 수정] 1600 x 7400 = 11.84. 남측 복도와 경계(SE y~452)에서 겹치지 않음 확인. | J20: low | K20: 길이 재측정 7.63->7.40m, 면적 12.21->11.84. 2F_dimension_SE/NE에서 코어 상단(NE y~790)~남측 복도 상단(SE y~452)을 13.7mm/px로 재면 약7.4m. 인권팀 외곽 세로 7400과도 정합. | v6: 외벽(창) 접면 없음/무수치 북벽 -> 띠 변경 없음
A21: 17 | B21: 2F | C21: ELE'V HALL + 북측 홀 | D21: DT-02 | G21: 27.71 | H21: 20.3 | I21: 2F_dimension_NE: 홀 북동부 5413(화장실M 동측~여직원 동벽) x 2000(여직원 하단~인권팀 상단 '2000') = 10.83; 화장실~코어 상단 띠 6.49x1.51 = 9.80 (폭은 그리드/도면비례); ELE'V 서측 1.55x2.67 - 원형기둥(0.4) = 3.74 => 24.37. 걸레받이 = 화장실 하부벽 약11.3 + 코어 상단/인권팀 상단 3.3 + 서측 3.0 약17.6 || [v5 수정] 북동부 5413x2000=10.83 + 화장실~코어 띠 6.49x1.51=9.80 + ELE'V 서측 2.8x2.67-0.4=7.08 => 27.71. 걸레받이: v4 17.6 + ELE'V 박스 서벽 2.7. | J21: low | K21: ELE'V 서측 블록 폭 오류 수정. v4는 1.55m로 잡았으나 2F_dimension_NW에서 서측 칸막이(x~975)~ELE'V 박스 서벽(x~1195)이 약215px x 13.7 = 2.9m(안목 약2.8m, 3F 동일 구조에서 v4도 2.8 사용). 2.8 x 2.67 - 원형기둥 0.4 = 7.08 로 정정, 면적 24.36->27.71. 걸레받이는 ELE'V 박스 서벽 약2.7m 추가해 17.6->20.3. | v6: 외벽(창) 접면 없음/무수치 북벽 -> 띠 변경 없음
A22: 18 | B22: 2F | C22: 인권팀 | D22: DT-02 | E22: 3490 | F22: 7170 | G22: 25.02 | H22: 6.98 | I22: 2F_dimension_SE: 가로 3490(안목, 115 벽 양쪽), 세로 5690+980+500=7170 (외곽 7400-115x2). 3.49x7.17. 걸레받이=상·하 고정벽 3.49x2 (좌우는 얇은 단선=유리 가정, 문 980 동측) | J22: mid | K22: ok | v6: 외벽(창) 접면 없음/무수치 북벽 -> 띠 변경 없음 | L22: 25.7 | M22: =IFERROR((G22-L22)/L22,"")
A23: 19 | B23: 2F | C23: OFFICE (서측, 03 DT) | D23: DT-03 | E23: 7200 | F23: 19150 | G23: 162.93 | H23: 37.1 | I23: 2F_dimension_NW: 450|6830(좌측 안목면~서버실/INFO벽) x (2661+980+270+3078=6989) = 47.73; 2F_dimension_SW: 850+6350=7200(안목~O.A RM 서측벽) x 12161(19150-6989) = 87.56; O.A RM 남측 보조구역 2.69x2.0(F-2 전이선까지) 5.38 + 소회의실-1 서측벽까지 1.71x3.56=6.09 + INFO/O.A 사이 1.71x1.99=3.40. 합150.15 - 독립기둥 2개(약0.5x0.5) 0.52 = 149.6. 서버실/INFO'MATION(무코드)·O.A RM(별도)·복도 제외. 걸레받이=북벽6.83+외벽 불투명구간 약7.1+서버실/INFO 서측벽6.99+O.A RM 서측벽(1441x2)2.88+O.A 북·남벽 3.6+소회의실-1 서측벽3.6+남측 불투명벽 6.1 약37.1 || [v6 창측 띠] 2F_dimension_NW '450'(창 내면~마감선) x 서측 길이 약18.64m(그리드E~마감 남단) + 2F_dimension_SW '555'(마감선~남측 창) x 남측 길이 약9.21m(서측 창 내면~O.A측 보조벽 x810) - SW 모서리 기둥 약0.5x0.41. 계산: 서측 450x18.64=+8.39 + 남측 555x9.21=+5.11 + 기둥1 공제=-0.21 = +13.29. 걸레받이는 창 하부(FCU 박스)라 변경 없음. | J23: mid | K23: 창측 띠 +13.29㎡ (2F_dimension_NW '450'(창 내면~마감선) x 서측 길이 약18.64m(그리드E~마감 남단) + 2F_dimension_SW '555'(마감선~남측 창) x 남측 길이 약9.21m(서측 창 내면~O.A측 보조벽 x810) - SW 모서리 기둥 약0.5x0.41). 면적 149.64->162.93. 이전 review: ok
A24: 20 | B24: 2F | C24: OFFICE (동측, 03 DT) | D24: DT-03 | E24: 7178 | F24: 19150 | G24: 142.55 | H24: 30 | I24: 2F_dimension_NE: 7178(여직원휴게실 동벽~동측 안목) x 6150(북측 안목~인권팀 상단) = 44.14; 인권팀 동측(5137=동안목-인권팀 동벽, 도면비례) x 7400(인권팀 외곽 세로 2F_dimension_SE) = 38.01; 인권팀 하부~남측 5600(2F_dimension_SE) x 7973(F-2 전이선 x=603~동안목) = 44.65; 금고 동벽~F-2선 0.93x3.59=3.34 => 130.14 - 기둥3개 0.78 = 129.4. 걸레받이=북벽7.18+동측 외벽 불투명구간 7.2+여직원 동벽4.05+인권팀 상·하벽4.0+금고 동벽3.35+남측 불투명 4.2 약30.0 || [v6 창측 띠] 2F_dimension_NE '439'(마감선~동측 창) x 동측 길이 약18.69m + 남측 '555' x 금고 동벽~동측 창 약9.34m - SE 모서리 기둥 약0.5x0.41. 금고 남벽 바깥 띠(약1.7x0.555)는 실 밖이라 제외. 계산: 동측 439x18.69=+8.21 + 남측 555x9.34=+5.18 + 기둥1 공제=-0.21 = +13.18. 걸레받이는 창 하부(FCU 박스)라 변경 없음. | J24: mid | K24: 창측 띠 +13.18㎡ (2F_dimension_NE '439'(마감선~동측 창) x 동측 길이 약18.69m + 남측 '555' x 금고 동벽~동측 창 약9.34m - SE 모서리 기둥 약0.5x0.41. 금고 남벽 바깥 띠(약1.7x0.555)는 실 밖이라 제외). 면적 129.37->142.55. 이전 review: ok
A25: 21 | B25: 3F | C25: 정책조정실 | D25: CT-01 | E25: 5250 | F25: 4890 | G25: 30.16 | H25: 17.6 | I25: 3F_dimension_NW: 4000+1250=5250(안목) x (3910+980=4890) = 25.67 + 하부 노치부 4000x559 = 2.24 => 27.91. 걸레받이=북5.25+서 불투명외벽 3.7+남4.0+동 3.91+기타 0.76 || [v6 창측 띠] 3F_dimension_NW 서측 창 내면~마감선(2F_dimension_NW '450'과 동일 외벽 구조, 3F는 숫자 미기재라 화면 약35px=480mm에서 450 준용) x 서측 길이 약5.0m. 계산: 서측 450x5.0=+2.25 = +2.25. 걸레받이는 창 하부(FCU 박스)라 변경 없음. | J25: mid | K25: 창측 띠 +2.25㎡ (3F_dimension_NW 서측 창 내면~마감선(2F_dimension_NW '450'과 동일 외벽 구조, 3F는 숫자 미기재라 화면 약35px=480mm에서 450 준용) x 서측 길이 약5.0m). 면적 27.91->30.16. 이전 review: ok | L25: 29.07 | M25: =IFERROR((G25-L25)/L25,"")
A26: 22 | B26: 3F | C26: 사무총장실 | D26: CT-01 | E26: 5600 | F26: 3660 | G26: 20.5 | H26: 13.5 | I26: 3F_dimension_NW: 가로 4200+250+980+320=5750 에서 차음벽 조립 약150 공제=5600, 세로 3910(서벽 길이)-약250(하부 붙박이장/차음벽)=3660. 5.6x3.66. 걸레받이=북5.6+서3.66+동3.66+남 개구 제외 0.6 | J26: low | K26: ok | v6: 외벽(창) 접면 없음/무수치 북벽 -> 띠 변경 없음 | L26: 19.55 | M26: =IFERROR((G26-L26)/L26,"")
A27: 23 | B27: 3F | C27: 사무국장실 | D27: CT-01 | E27: 3384 | F27: 4445 | G27: 14.83 | H27: 9.6 | I27: 3F_dimension_SW: 가로 980+300+2104=3384, 세로 3895(3F_dimension_SE '3895'). 걸레받이=서3.895+동3.895+남 불투명 1.8 (전면 유리 제외) || [v6 창측 띠] 3F_dimension_SW/SE '3895' 끝~창 '550' x 가로 3384 - 기둥 약0.21. 계산: 남측 550x3.384=+1.86 + 기둥1 공제=-0.21 = +1.65. 걸레받이는 창 하부(FCU 박스)라 변경 없음. | J27: mid | K27: 창측 띠 +1.65㎡ (3F_dimension_SW/SE '3895' 끝~창 '550' x 가로 3384 - 기둥 약0.21). 면적 13.18->14.83. 이전 review: ok | L27: 16.18 | M27: =IFERROR((G27-L27)/L27,"")
A28: 24 | B28: 3F | C28: 중회의실(임원휴게실) | D28: CT-02 | E28: 3198 | F28: 4445 | G28: 14.22 | H28: 3.9 | I28: 3F_dimension_SE/SW: 가로 3198, 세로 3895. 걸레받이=서측벽 3.895+동측 폴딩 칸막이 3.895 (가정) || [v5 수정] 걸레받이=서측 고정벽 3.895 (동측 폴딩도어 제외). || [v6 창측 띠] 3F_dimension_SE '3895' 끝~창 '550' x 가로 3198 (기둥 없음). 계산: 남측 550x3.198=+1.76 = +1.76. 걸레받이는 창 하부(FCU 박스)라 변경 없음. | J28: mid | K28: 창측 띠 +1.76㎡ (3F_dimension_SE '3895' 끝~창 '550' x 가로 3198 (기둥 없음)). 면적 12.46->14.22. 이전 review: 걸레받이 수정 7.79->3.9. 동측 폴딩도어(ESC-04)는 걸레받이 없음. 서측 사무국장실 칸막이 고정벽 3.895만 인정. | L28: 13.98 | M28: =IFERROR((G28-L28)/L28,"")
A29: 25 | B29: 3F | C29: 중회의실-1 | D29: CT-02 | E29: 3198 | F29: 4445 | G29: 14.01 | H29: 0 | I29: 3F_dimension_SE: 가로 3198, 세로 3895. 걸레받이=양측 폴딩 칸막이 3.895x2 (가정) || [v5 수정] 양측 폴딩도어, 전면 유리 => 0. || [v6 창측 띠] 3F_dimension_SE '3895' 끝~창 '550' x 가로 3198 - 기둥 약0.21. 계산: 남측 550x3.198=+1.76 + 기둥1 공제=-0.21 = +1.55. 걸레받이는 창 하부(FCU 박스)라 변경 없음. | J29: mid | K29: 창측 띠 +1.55㎡ (3F_dimension_SE '3895' 끝~창 '550' x 가로 3198 - 기둥 약0.21). 면적 12.46->14.01. 이전 review: 걸레받이 수정 7.79->0. 양측 폴딩도어 칸막이, 전면 유리 => 벽 구간 없음. | L29: 13.84 | M29: =IFERROR((G29-L29)/L29,"")
A30: 26 | B30: 3F | C30: 대회의실 | D30: CT-02 | E30: 5098 | F30: 4445 | G30: 22.66 | H30: 3.9 | I30: 3F_dimension_SE: 가로 5098, 세로 3895. 걸레받이=서측 폴딩 3.895+동측 고정벽 3.895 || [v5 수정] 걸레받이=동측 고정벽 3.895 (서측 폴딩도어 제외). || [v6 창측 띠] 3F_dimension_SE '3895' 끝~창 '550' x 가로 5098 (기둥 없음). 계산: 남측 550x5.098=+2.80 = +2.80. 걸레받이는 창 하부(FCU 박스)라 변경 없음. | J30: mid | K30: 창측 띠 +2.80㎡ (3F_dimension_SE '3895' 끝~창 '550' x 가로 5098 (기둥 없음)). 면적 19.86->22.66. 이전 review: 걸레받이 수정 7.79->3.9. 서측 폴딩도어 제외, 동측 고정벽 3.895만 인정. | L30: 22.85 | M30: =IFERROR((G30-L30)/L30,"")
A31: 27 | B31: 3F | C31: 접견실 | D31: CT-03 | E31: 5145 | F31: 6900 | G31: 42.05 | H31: 15.3 | I31: 3F_dimension_SW: 850+980+3315=5145(가로), 세로 5400+520+980=6900(동벽 길이). 5.145x6.9=35.50 + 서측 곡면 베이(현창) 면적 약3.5(chord 5.5m x 높이 1.05m x 2/3, 도면비례 추정) - 기둥 0.39 = 38.61. 걸레받이=동벽 6.9-문0.98+북5.145+남(슬라이딩 도어 0.98 제외)4.17, 곡면 창 제외 || [v6 창측 띠] 3F_dimension_NW/SW 서측 창 450(준용) x 직선 1.64m + 곡면 현창 마감호~창호 사이 띠 450 x 호길이 약6.0m (v5 베이 가산은 마감호 안쪽까지만 포함). 계산: 서측 직선 450x1.64=+0.74 + 곡면 베이 띠 450x약6.0=+2.70 = +3.44. 걸레받이는 창 하부(FCU 박스)라 변경 없음. | J31: mid | K31: 창측 띠 +3.44㎡ (3F_dimension_NW/SW 서측 창 450(준용) x 직선 1.64m + 곡면 현창 마감호~창호 사이 띠 450 x 호길이 약6.0m (v5 베이 가산은 마감호 안쪽까지만 포함)). 면적 38.61->42.05. 이전 review: ok | L31: 39.55 | M31: =IFERROR((G31-L31)/L31,"")
A32: 28 | B32: 3F | C32: 협회장실 | D32: CT-03 | E32: 5145 | F32: 4700 | G32: 35.98 | H32: 15.3 | I32: 3F_dimension_SW: 상부 5145 x (940+300+1170+105+2295 중 슬라이딩벽 아래 약4700) = 24.18; 하부 4645('4645' 숫자) x 1500(105+410+980+105 구간) = 6.97; 기둥 0.13 공제 => 31.02. 걸레받이=동벽 3.76+북 4.17+서 불투명 3.5+남 불투명 2.85+하부 1.0 || [v6 창측 띠] 3F_dimension_SW 남측 '450'(마감선~창) x 창 내면~서벽(x512) 5.12m + 서측 450(준용) x 6.37m - SW 기둥 약0.21. 계산: 서측 450x6.37=+2.87 + 남측 450x5.12=+2.30 + 기둥1 공제=-0.21 = +4.96. 걸레받이는 창 하부(FCU 박스)라 변경 없음. | J32: mid | K32: 창측 띠 +4.96㎡ (3F_dimension_SW 남측 '450'(마감선~창) x 창 내면~서벽(x512) 5.12m + 서측 450(준용) x 6.37m - SW 기둥 약0.21). 면적 31.02->35.98. 이전 review: ok | L32: 35.18 | M32: =IFERROR((G32-L32)/L32,"")
A33: 29 | B33: 3F | C33: 창고 | D33: DE-01 | E33: 2180 | F33: 4230 | G33: 9.05 | H33: 11.84 | I33: 3F_dimension_NE: 가로 1100+980+100=2180, 세로 4230. 기둥 돌출 0.17 공제 => 9.05. 걸레받이=둘레12.82-문980=11.84 | J33: mid | K33: ok | v6: 외벽(창) 접면 없음/무수치 북벽 -> 띠 변경 없음
A34: 30 | B34: 3F | C34: 비서 | D34: DT-01 | E34: 4440 | F34: 2295 | G34: 10.19 | H34: 10.8 | I34: 3F_dimension_SW: 가로 2000+799+190+1450(+385 이중벽 제외)=4439, 세로 2295. 4.44x2.295. 걸레받이=상부 벽 1.745+동 2.295+서 2.295+하부벽 4.44 (상부 붙박이장 2.12·개구 0.8 제외) | J34: mid | K34: ok | v6: 외벽(창) 접면 없음/무수치 북벽 -> 띠 변경 없음
A35: 31 | B35: 3F | C35: LOUNGE | D35: DT-02 | E35: 5740 | F35: 9250 | G35: 53.09 | H35: 16 | I35: 3F_dimension_NW/SW: 폭 접견실 동벽~코어 서벽 약5.74m(도면비례), 길이 사무총장실 하단~코어 하부 약9.25m(도면비례, 1500/2400/4500 숫자와 정합). 숫자 직접 표기 없어 신뢰도 낮음. 걸레받이=서측 접견실/협회장실 동벽 7.2+북 1.0+동 코어벽 7.8 | J35: low | K35: ok | v6: 외벽(창) 접면 없음/무수치 북벽 -> 띠 변경 없음
A36: 32 | B36: 3F | C36: CORRIDOR 남측 | D36: DT-02 | E36: 17080 | F36: 2000 | G36: 34.16 | H36: 10.2 | I36: 3F_dimension_SE: 세로 2000('2000' 숫자) x 가로 협회장실 동벽~F-2 전이선(SE x=606) 약17.08m(도면비례). 걸레받이=코어 하부벽 8.5+비서 상부벽 1.745. 전면 유리 제외 | J36: low | K36: ok | v6: 외벽(창) 접면 없음/무수치 북벽 -> 띠 변경 없음
A37: 33 | B37: 3F | C37: CORRIDOR 동측 | D37: DT-02 | E37: 2000 | F37: 7230 | G37: 14.46 | H37: 8.9 | I37: 3F_dimension_NE/SE: 폭 2000(코어 동측~J구역 서벽 '2000') x 길이 약7.23m(코어 상단~코어 하단, '4000|1500|1500' 정합). 걸레받이=코어 동벽 5.7+J구역 서벽 3.2 | J37: mid | K37: ok | v6: 외벽(창) 접면 없음/무수치 북벽 -> 띠 변경 없음
A38: 34 | B38: 3F | C38: CORRIDOR 북측 | D38: DT-02 | E38: 3680 | F38: 1815 | G38: 6.68 | H38: 3 | I38: 3F_dimension_NE: 1680+2000=3680 x 1815('1815' 숫자). 걸레받이=창고 전면벽 1.3+코어 상단벽 1.65 | J38: mid | K38: ok | v6: 외벽(창) 접면 없음/무수치 북벽 -> 띠 변경 없음
A39: 35 | B39: 3F | C39: ELE'V HALL | D39: DT-02 | G39: 16.36 | H39: 13.7 | I39: 3F_dimension_NW: 화장실 하부~코어 상단 띠 6.43x1.5('1500' 자동문 구간 높이) = 9.64 + ELE'V 서측 2.8x2.4('2400') = 6.72 => 16.36. 걸레받이=화장실 하벽 4.7+코어 상단 5.3+서벽 2.4+기타 | J39: low | K39: ok | v6: 외벽(창) 접면 없음/무수치 북벽 -> 띠 변경 없음
A40: 36 | B40: 3F | C40: OFFICE (동측 공보/총무/입법/법제/공제) | D40: DT-03 | G40: 129.05 | H40: 18.3 | I40: 3F_dimension_NE/SE: 북측 4.562x6.15(대회협력실 동벽~동안목 x 안목~'1815' 하단) 28.06; 대회협력실 하부 4.275x1.815+모따기 삼각 0.78=8.54; 5682+700=6382 x 6.93(J구역 하단까지) 44.23; 동측 곡면 베이 약3.8(도면비례); F-2 전이선 동측 7.864x2000 15.73; 대회의실 동측 4.59x3895 17.88; 기둥2 -0.52 => 117.7. 걸레받이=북 4.56+동 불투명 7.1+대회의실 동벽 3.9+남 불투명 2.7 || [v6 창측 띠] 3F_dimension_NE '5682|700|700'(기둥박스 외면~창 700, v5 경계가 5682+700에서 끝난 구간은 700) + 마감선이 경계인 구간은 2F '439' 준용 440 + 곡면 현창 띠 440 x 호길이 6.0 + 남측 '550' x 대회의실 동벽~동측 창 5.44 - 기둥 0.21. 계산: 동측 북블록 440x5.71=+2.51 + 동측 직선 700x0.93=+0.65 + 동측 곡면 베이 띠 440x6.0=+2.64 + 동측 남블록 440x6.26=+2.75 + 남측 550x5.44=+2.99 + 기둥1 공제=-0.21 = +11.34. 걸레받이는 창 하부(FCU 박스)라 변경 없음. | J40: low | K40: 창측 띠 +11.34㎡ (3F_dimension_NE '5682|700|700'(기둥박스 외면~창 700, v5 경계가 5682+700에서 끝난 구간은 700) + 마감선이 경계인 구간은 2F '439' 준용 440 + 곡면 현창 띠 440 x 호길이 6.0 + 남측 '550' x 대회의실 동벽~동측 창 5.44 - 기둥 0.21). 면적 117.71->129.05. 이전 review: ok

Sheet 검토 필요
A1: 견적팀·발주처에 확인할 항목 (AI가 혼자 결정하면 안 되는 경계)
A3: # | B3: 항목 | C3: 근거 | D3: 수량 영향 | E3: 질문
A4: 1 | B4: 창측 띠(FCU 박스 구간) 포함 여부 | C4: 치수선이 창 앞에서 끝나고 555/450/439mm 띠가 별도 기재. AI가 처음엔 이 띠를 빠뜨려 창가 회의실·임원실 8곳이 10~19% 작게 나옴 | D4: +61.1㎡ (2F 31.4, 3F 29.8) | E4: FCU 박스 하부까지 바닥재를 까나요, 박스 앞에서 끊나요?
A5: 2 | B5: 내역 코드 번호 ≠ 도면 범례 번호 | C5: 도면에는 CT-01~03만 있는데 내역에는 CT-01~05. 내역 CT-01(101㎡)이 도면 CT-01 실(B1 대회의실 135㎡ 단독)보다 작음 → 번호 체계가 다름 | D5: 코드별 대조 불가 | E5: 내역 CT-01~05가 각각 어느 실인지 매핑표가 있나요?
A6: 3 | B6: 데코타일 면적 차이 +103㎡ | C6: 도면에서 코드가 붙은 DT 면적 760㎡ vs 내역 863㎡. 후보: 태그 없이 문구만 있는 실, 서버실·INFO·O.A ROOM 등 무코드 실, B1 미표기 구역 | D6: +103㎡ | E6: 코드 태그가 없는 실(서버실 등)도 데코타일로 산출하나요?
A7: 4 | B7: 태그 없는 실의 마감 문구 | C7: B1 기사대기실 '~DELUXE TILE FIN.', 2F 직원휴게실 '~DECO TILE FIN.' 등 코드 태그 없이 문구만 있음 | D7: 약 21㎡ | E7: 문구만 있는 실도 해당 코드로 산출하나요?
A8: 5 | B8: 단상(우드플로링) 하부 | C8: B1 다목적 대회의실 단상 6000x1200 - 내역에 '단상설치 1EA' 별도 | D8: -7.2㎡ (CT-01) | E8: 단상 하부에 카펫을 깔지 않는 게 맞나요?
A9: 6 | B9: 규격 불일치 DE-01 | C9: 내역 300x300 ↔ 도면 범례 450x450 | D9: 단가 영향 | E9: 최종 규격은 어느 쪽인가요?
A10: 7 | B10: 규격 불일치 DT-01 | C10: 내역 450x450 ↔ MATERIAL LIST 600x600 T5 | D10: 단가 영향 | E10: 최종 규격은 어느 쪽인가요?
A11: 8 | B11: 폴딩도어 구간 걸레받이 | C11: 이동식 칸막이 하부는 벽이 아니므로 제외로 처리 | D11: 수 m | E11: 폴딩도어 하부 걸레받이 처리 기준은?
A12: 9 | B12: 걸레받이 총량 차이 | C12: AI 460m vs 내역 765m. 열린 사무실 외곽·기둥 둘레·가구 뒤 처리 기준이 다른 것으로 추정 | D12: -305m | E12: 기둥 둘레와 붙박이 가구 뒤에도 걸레받이를 넣나요?

Sheet 실험 기록
A1: 하네스 실험 기록 - 같은 도면, 같은 모델, 지시·도구만 바꿔 6회 실행
A3: 버전 | B3: 바꾼 것 | C3: 실 단위 평균오차 | D3: ±5% 이내 실 | E3: 근거 있는 면적 비율 | F3: 합계 오차(도면 기준)
A4: v1 | B4: 도면 4장 주고 '물량 산출해줘' | C4: 채점 불가(근거 없음) | D4: 0/19 | E4: 0 | F4: -0.026
A5: v2 | B5: 실별 표 형식 + 근거·신뢰도 기재 강제 | C5: 0.163 | D5: 6/19 | E5: 0.343 | F5: -0.154
A6: v3 | B6: 입력 추가: 치수 도면 + 고해상도 4분할 타일, 적힌 숫자만 사용 | C6: 0.143 | D6: 4/19 | E6: 0.503 | F6: -0.057
A7: v4 | B7: 견적 실무 규칙 R1~R7 (안목, 기둥 공제, 이중계산 금지, 정미량, 층별 검산) | C7: 0.088 | D7: 8/19 | E7: 0.64 | F7: -0.046
A8: v5 | B8: 검토자 에이전트가 v4를 도면과 대조해 수정 | C8: 0.088 | D8: 8/19 | E8: 0.668 | F8: -0.085
A9: v6 | B9: 검증 데이터에서 찾은 오차 패턴(창측 띠) 규칙 추가 | C9: 0.043 | D9: 13/19 | E9: 0.675 | F9: -0.034
A11: 주의: v6 규칙은 검증 세트(19실)의 오차를 보고 찾았고 같은 세트로 평가했으므로 낙관적일 수 있음. 공사 1건·버전별 1회 실행.
